Workbook

Sheet 财务历史
A1: 指标 | B1: 2022A | C1: 2023A | D1: 2024A | E1: 2025A
A2: 收入 ($M) | B2: 26974000000 | C2: 60922000000 | D2: 130497000000 | E2: 215938000000
A3: 收入增速 | C3: 1.2585 | D3: 1.142 | E3: 0.6547
A4: 毛利 ($M) | B4: 15356000000 | C4: 44301000000 | D4: 97858000000 | E4: 153463000000
A5: 毛利率 | B5: 0.5693 | C5: 0.7272 | D5: 0.7499 | E5: 0.7107
A6: 研发费用 ($M) | B6: 7339000000 | C6: 8675000000 | D6: 12914000000 | E6: 18497000000
A7: 研发费用率 | B7: 0.2721 | C7: 0.1424 | D7: 0.099 | E7: 0.0857
A8: EBIT ($M) | B8: 5577000000 | C8: 32972000000 | D8: 81453000000 | E8: 130387000000
A9: EBIT利润率 | B9: 0.2068 | C9: 0.5412 | D9: 0.6242 | E9: 0.6038
A10: 净利润 ($M) | B10: 4368000000 | C10: 29760000000 | D10: 72880000000 | E10: 120067000000
A11: 净利率 | B11: 0.1619 | C11: 0.4885 | D11: 0.5585 | E11: 0.556

Sheet 分部历史
A1: 分部 | B1: 2024A | C1: 2025A | D1: 2026A
A2: Data Center | B2: 47.52 | C2: 115.19 | D2: 193.74
A3: Gaming | B3: 10.45 | C3: 11.35 | D3: 16.04
A4: Pro Visualization | B4: 1.55 | C4: 1.88 | D4: 3.19
A5: Automotive | B5: 1.09 | C5: 1.69 | D5: 2.35
A6: OEM & Other | B6: 0.31 | C6: 0.39 | D6: 0.62
A7: Data Center 占比 | B7: =B2/B7 | C7: =C2/C7 | D7: =D2/D7
A8: Gaming 占比 | B8: =B3/B7 | C8: =C3/C7 | D8: =D3/D7
A9: Pro Visualization 占比 | B9: =B4/B7 | C9: =C4/C7 | D9: =D4/D7
A10: Automotive 占比 | B10: =B5/B7 | C10: =C5/C7 | D10: =D5/D7
A11: OEM & Other 占比 | B11: =B6/B7 | C11: =C6/C7 | D11: =D6/D7

Sheet 假设
A1: 活跃情景 | B1: 2
A2: 指标 | C2: Bear | D2: Base | E2: Bull | F2: 活跃值 | G2: 来源/推导依据
A3: --- Data Center ---
A4: AIDC CapEx 起始 ($B) | C4: 500 | D4: 550 | E4: 600 | F4: =INDEX(C4:E4,$B$1) | G4: AIDC CapEx 2025E: Hyperscaler CapEx (MSFT+GOOG+META+AMZN) ≈$300B + Enterprise ≈$200B = $550B
A5: AIDC CapEx CAGR Y1-3 | C5: 0.12 | D5: 0.28 | E5: 0.42 | F5: =INDEX(C5:E5,$B$1) | G5: Base 28%: Hyperscaler guided 30-40% growth, normalize to 28% for TAM
A6: AIDC CapEx CAGR Y4-6 | C6: 0.08 | D6: 0.16 | E6: 0.25 | F6: =INDEX(C6:E6,$B$1) | G6: Deceleration phase: AI training demand normalizes, inference scales linearly
A7: AIDC CapEx CAGR Y7-10 | C7: 0.05 | D7: 0.08 | E7: 0.1 | F7: =INDEX(C7:E7,$B$1) | G7: Long-term: AI infra utility, growth converges to GDP+inflation (~5-8%)
A8: NVDA可触达率 | C8: 0.395 | D8: 0.415 | E8: 0.435 | F8: =INDEX(C8:E8,$B$1) | G8: 41.5%: NVDA可触达=AIDC中GPU+IB网络部分。校准:$194B收入/85%市占率=$228B可触达,$228B/$550B=41.5%
A9: AI GPU市占率 2025 | C9: 0.85 | D9: 0.85 | E9: 0.85 | F9: =INDEX(C9:E9,$B$1) | G9: 85%: AI GPU market share (Visual Capitalist 86%, CarbonCredits 92%, Mizuho 70-95%, Yahoo 85%)
A10: AI GPU市占率 2035 | C10: 0.7 | D10: 0.85 | E10: 0.9 | F10: =INDEX(C10:E10,$B$1) | G10: Base 85% hold: CUDA lock-in+NVLink+software. Bear 70% (AMD/custom ASIC). Bull 90% (networking gains)
A11: --- Gaming ---
A12: Gaming起始收入 ($B) | C12: 16 | D12: 16 | E12: 16 | F12: =INDEX(C12:E12,$B$1) | G12: Gaming FY2026 $16.0B, GeForce GPU市场成熟但AI PC gaming带来增量
A13: Gaming CAGR Y1-3 | C13: 0.03 | D13: 0.1 | E13: 0.15 | F13: =INDEX(C13:E13,$B$1) | G13: Base 10%: 受益AI PC gaming + 换机周期,但受DC产能挤压
A14: Gaming CAGR Y4-6 | C14: 0 | D14: 0.08 | E14: 0.12 | F14: =INDEX(C14:E14,$B$1) | G14: Base 8%: 增速趋稳
A15: Gaming CAGR Y7-10 | C15: -0.03 | D15: 0.05 | E15: 0.08 | F15: =INDEX(C15:E15,$B$1) | G15: Base 5%: 成熟业务,接近GDP+
A16: --- Pro Visualization ---
A17: ProViz起始收入 ($B) | C17: 3.2 | D17: 3.2 | E17: 3.2 | F17: =INDEX(C17:E17,$B$1) | G17: Pro Viz FY2026 $3.2B, RTX Pro工作站GPU受益AI设计师需求
A18: ProViz CAGR Y1-3 | C18: 0.1 | D18: 0.25 | E18: 0.4 | F18: =INDEX(C18:E18,$B$1) | G18: Base 25%: AI工作站需求快速增长,RXT Pro GPU渗透率提升
A19: ProViz CAGR Y4-6 | C19: 0.05 | D19: 0.18 | E19: 0.25 | F19: =INDEX(C19:E19,$B$1) | G19: Base 18%: 增速从高基数回落
A20: ProViz CAGR Y7-10 | C20: 0.02 | D20: 0.1 | E20: 0.15 | F20: =INDEX(C20:E20,$B$1) | G20: Base 10%: 成熟增长
A21: --- Automotive ---
A22: Auto起始收入 ($B) | C22: 2.4 | D22: 2.4 | E22: 2.4 | F22: =INDEX(C22:E22,$B$1) | G22: Automotive FY2026 $2.4B, 自动驾驶+物理AI平台(Alpamayo+Mercedes)
A23: Auto CAGR Y1-3 | C23: 0.2 | D23: 0.4 | E23: 0.6 | F23: =INDEX(C23:E23,$B$1) | G23: Base 40%: 自动驾驶市场快速增长,物理AI早期商业化
A24: Auto CAGR Y4-6 | C24: 0.12 | D24: 0.3 | E24: 0.4 | F24: =INDEX(C24:E24,$B$1) | G24: Base 30%: 渗透率提升,维持高增长
A25: Auto CAGR Y7-10 | C25: 0.08 | D25: 0.15 | E25: 0.25 | F25: =INDEX(C25:E25,$B$1) | G25: Base 15%: 增速随规模扩大而降
A26: --- OEM & Other ---
A27: OEM起始收入 ($B) | C27: 0.6 | D27: 0.6 | E27: 0.6 | F27: =INDEX(C27:E27,$B$1) | G27: OEM FY2026 $0.6B, 体量太小不增长建模
A28: --- 利润率 ---
A29: 起始毛利率 | C29: 0.71 | D29: 0.71 | E29: 0.71 | F29: =INDEX(C29:E29,$B$1) | G29: 71.1%: Actual FY2026 Q4. Blackwell ramp compressing from H100 peak 75%
A30: 终年毛利率 | C30: 0.55 | D30: 0.61 | E30: 0.71 | F30: =INDEX(C30:E30,$B$1) | G30: Base 61%: Competition+customer bargaining. Still premium vs historical 55-60%
A31: 起始费用率 | C31: 0.17 | D31: 0.17 | E31: 0.17 | F31: =INDEX(C31:E31,$B$1) | G31: 17%: R&D 12% + SG&A 4.3%. Peak efficiency due to revenue scale
A32: 终年费用率 | C32: 0.25 | D32: 0.2 | E32: 0.16 | F32: =INDEX(C32:E32,$B$1) | G32: Base 20%: R&D intensity rises as growth slows
A33: 税率 | C33: 0.14 | D33: 0.13 | E33: 0.13 | F33: =INDEX(C33:E33,$B$1) | G33: 13%: NVDA effective rate FY2025. R&D credits + foreign benefits
A34: --- 估值 ---
A35: 起始PE | C35: 30 | D35: 40 | E35: 50 | F35: =INDEX(C35:E35,$B$1) | G35: Base 起始40x: 低于5年中位50x，增长放缓。Bear 30x Bull 50x
A36: 终年PE | C36: 18 | D36: 25 | E36: 35 | F36: =INDEX(C36:E36,$B$1) | G36: Base 终端25x: Intel/CSCO成熟期PE~20-25x，NVDA因CUDA生态有溢价
A37: 股份数 (M) | C37: 24434 | D37: 24434 | E37: 24434 | F37: =INDEX(C37:E37,$B$1) | G37: 24,434M: Current shares outstanding from yfinance

Sheet 预测
A1: 指标 | B1: 2025A | C1: 2026E | D1: 2027E | E1: 2028E | F1: 2029E | G1: 2030E | H1: 2031E | I1: 2032E | J1: 2033E | K1: 2034E | L1: 2035E
A2: --- 收入推导: Data Center ---
A3: AIDC CapEx 起始 ($B) | B3: ='假设'!$F$4 | C3: ='假设'!$F$4 | D3: ='假设'!$F$4 | E3: ='假设'!$F$4 | F3: ='假设'!$F$4 | G3: ='假设'!$F$4 | H3: ='假设'!$F$4 | I3: ='假设'!$F$4 | ... L3: ='假设'!$F$4
A4: AIDC CapEx CAGR Y1-3 | B4: ='假设'!$F$5 | C4: ='假设'!$F$5 | D4: ='假设'!$F$5 | E4: ='假设'!$F$5 | F4: ='假设'!$F$5 | G4: ='假设'!$F$5 | H4: ='假设'!$F$5 | I4: ='假设'!$F$5 | ... L4: ='假设'!$F$5
A5: AIDC CapEx CAGR Y4-6 | B5: ='假设'!$F$6 | C5: ='假设'!$F$6 | D5: ='假设'!$F$6 | E5: ='假设'!$F$6 | F5: ='假设'!$F$6 | G5: ='假设'!$F$6 | H5: ='假设'!$F$6 | I5: ='假设'!$F$6 | ... L5: ='假设'!$F$6
A6: AIDC CapEx CAGR Y7-10 | B6: ='假设'!$F$7 | C6: ='假设'!$F$7 | D6: ='假设'!$F$7 | E6: ='假设'!$F$7 | F6: ='假设'!$F$7 | G6: ='假设'!$F$7 | H6: ='假设'!$F$7 | I6: ='假设'!$F$7 | ... L6: ='假设'!$F$7
A7: AIDC CapEx ($B) | B7: ='假设'!$F$4 | C7: =C3*(1+C4) | D7: =C7*(1+D4) | E7: =D7*(1+E5) | F7: =E7*(1+F5) | G7: =F7*(1+G5) | H7: =G7*(1+H6) | I7: =H7*(1+I6) | J7: =I7*(1+J6) | K7: =J7*(1+K6) | L7: =K7*(1+L6)
A8: NVDA可触达率 | B8: ='假设'!$F$8 | C8: ='假设'!$F$8 | D8: ='假设'!$F$8 | E8: ='假设'!$F$8 | F8: ='假设'!$F$8 | G8: ='假设'!$F$8 | H8: ='假设'!$F$8 | I8: ='假设'!$F$8 | ... L8: ='假设'!$F$8
A9: 可触达市场 ($B) | B9: =B7*B8 | C9: =C7*C8 | D9: =D7*D8 | E9: =E7*E8 | F9: =F7*F8 | G9: =G7*G8 | H9: =H7*H8 | I9: =I7*I8 | ... L9: =L7*L8
A10: AI GPU市占率起始 | B10: ='假设'!$F$9 | C10: ='假设'!$F$9 | D10: ='假设'!$F$9 | E10: ='假设'!$F$9 | F10: ='假设'!$F$9 | G10: ='假设'!$F$9 | H10: ='假设'!$F$9 | I10: ='假设'!$F$9 | ... L10: ='假设'!$F$9
A11: AI GPU市占率终年 | B11: ='假设'!$F$10 | C11: ='假设'!$F$10 | D11: ='假设'!$F$10 | E11: ='假设'!$F$10 | F11: ='假设'!$F$10 | G11: ='假设'!$F$10 | H11: ='假设'!$F$10 | I11: ='假设'!$F$10 | ... L11: ='假设'!$F$10
A12: 市占率 | B12: =B10 | C12: =C10+(C11-C10)*1/10 | D12: =D10+(D11-D10)*2/10 | E12: =E10+(E11-E10)*3/10 | F12: =F10+(F11-F10)*4/10 | G12: =G10+(G11-G10)*5/10 | H12: =H10+(H11-H10)*6/10 | I12: =I10+(I11-I10)*7/10 | J12: =J10+(J11-J10)*8/10 | K12: =K10+(K11-K10)*9/10 | L12: =L10+(L11-L10)*10/10
A13: DC收入 ($B) | B13: =B9*B12 | C13: =C9*C12 | D13: =D9*D12 | E13: =E9*E12 | F13: =F9*F12 | G13: =G9*G12 | H13: =H9*H12 | I13: =I9*I12 | ... L13: =L9*L12
A15: -- Gaming --
A16: Gaming收入 ($B) | B16: ='假设'!$F$12 | C16: =B16*(1+'假设'!$F$13) | D16: =C16*(1+'假设'!$F$13) | E16: =D16*(1+'假设'!$F$13) | F16: =E16*(1+'假设'!$F$14) | G16: =F16*(1+'假设'!$F$14) | H16: =G16*(1+'假设'!$F$14) | I16: =H16*(1+'假设'!$F$15) | J16: =I16*(1+'假设'!$F$15) | K16: =J16*(1+'假设'!$F$15) | L16: =K16*(1+'假设'!$F$15)
A17: -- Pro Visualization --
A18: Pro Visualization收入 ($B) | B18: ='假设'!$F$17 | C18: =B18*(1+'假设'!$F$18) | D18: =C18*(1+'假设'!$F$18) | E18: =D18*(1+'假设'!$F$18) | F18: =E18*(1+'假设'!$F$19) | G18: =F18*(1+'假设'!$F$19) | H18: =G18*(1+'假设'!$F$19) | I18: =H18*(1+'假设'!$F$20) | J18: =I18*(1+'假设'!$F$20) | K18: =J18*(1+'假设'!$F$20) | L18: =K18*(1+'假设'!$F$20)
A19: -- Automotive --
A20: Automotive收入 ($B) | B20: ='假设'!$F$22 | C20: =B20*(1+'假设'!$F$23) | D20: =C20*(1+'假设'!$F$23) | E20: =D20*(1+'假设'!$F$23) | F20: =E20*(1+'假设'!$F$24) | G20: =F20*(1+'假设'!$F$24) | H20: =G20*(1+'假设'!$F$24) | I20: =H20*(1+'假设'!$F$25) | J20: =I20*(1+'假设'!$F$25) | K20: =J20*(1+'假设'!$F$25) | L20: =K20*(1+'假设'!$F$25)
A21: -- OEM & Other --
A22: OEM & Other收入 ($B) | B22: ='假设'!$F$27 | C22: ='假设'!$F$27 | D22: ='假设'!$F$27 | E22: ='假设'!$F$27 | F22: ='假设'!$F$27 | G22: ='假设'!$F$27 | H22: ='假设'!$F$27 | I22: ='假设'!$F$27 | ... L22: ='假设'!$F$27
A23: --- 总收入汇总 ---
A24: 总收入 ($B) | B24: 215938000000 | C24: =C13+C16+C18+C20+C22 | D24: =D13+D16+D18+D20+D22 | E24: =E13+E16+E18+E20+E22 | F24: =F13+F16+F18+F20+F22 | G24: =G13+G16+G18+G20+G22 | H24: =H13+H16+H18+H20+H22 | I24: =I13+I16+I18+I20+I22 | J24: =J13+J16+J18+J20+J22 | ... L24: =L13+L16+L18+L20+L22
A25: 总收入增速 | B25: 0.6547 | C25: =(C24*1000-215938000000.0)/215938000000.0 | D25: =(D24-C24)/C24 | E25: =(E24-D24)/D24 | F25: =(F24-E24)/E24 | G25: =(G24-F24)/F24 | H25: =(H24-G24)/G24 | I25: =(I24-H24)/H24 | J25: =(J24-I24)/I24 | K25: =(K24-J24)/J24 | L25: =(L24-K24)/K24
A27: --- 利润推导 ---
A28: 起始毛利率 | B28: ='假设'!$F$29 | C28: ='假设'!$F$29 | D28: ='假设'!$F$29 | E28: ='假设'!$F$29 | F28: ='假设'!$F$29 | G28: ='假设'!$F$29 | H28: ='假设'!$F$29 | I28: ='假设'!$F$29 | ... L28: ='假设'!$F$29
A29: 终年毛利率 | B29: ='假设'!$F$30 | C29: ='假设'!$F$30 | D29: ='假设'!$F$30 | E29: ='假设'!$F$30 | F29: ='假设'!$F$30 | G29: ='假设'!$F$30 | H29: ='假设'!$F$30 | I29: ='假设'!$F$30 | ... L29: ='假设'!$F$30
A30: 毛利率 | B30: 0.7107 | C30: =C28+(C29-C28)*0/9 | D30: =D28+(D29-D28)*1/9 | E30: =E28+(E29-E28)*2/9 | F30: =F28+(F29-F28)*3/9 | G30: =G28+(G29-G28)*4/9 | H30: =H28+(H29-H28)*5/9 | I30: =I28+(I29-I28)*6/9 | J30: =J28+(J29-J28)*7/9 | K30: =K28+(K29-K28)*8/9 | L30: =L28+(L29-L28)*9/9
A31: 毛利 ($B) | B31: 153467136600 | C31: =C24*C30 | D31: =D24*D30 | E31: =E24*E30 | F31: =F24*F30 | G31: =G24*G30 | H31: =H24*H30 | I31: =I24*I30 | J31: =J24*J30 | ... L31: =L24*L30
A32: 起始费用率 | B32: ='假设'!$F$31 | C32: ='假设'!$F$31 | D32: ='假设'!$F$31 | E32: ='假设'!$F$31 | F32: ='假设'!$F$31 | G32: ='假设'!$F$31 | H32: ='假设'!$F$31 | I32: ='假设'!$F$31 | ... L32: ='假设'!$F$31
A33: 终年费用率 | B33: ='假设'!$F$32 | C33: ='假设'!$F$32 | D33: ='假设'!$F$32 | E33: ='假设'!$F$32 | F33: ='假设'!$F$32 | G33: ='假设'!$F$32 | H33: ='假设'!$F$32 | I33: ='假设'!$F$32 | ... L33: ='假设'!$F$32
A34: 费用率 | B34: 0.1069 | C34: =C32+(C33-C32)*0/9 | D34: =D32+(D33-D32)*1/9 | E34: =E32+(E33-E32)*2/9 | F34: =F32+(F33-F32)*3/9 | G34: =G32+(G33-G32)*4/9 | H34: =H32+(H33-H32)*5/9 | I34: =I32+(I33-I32)*6/9 | J34: =J32+(J33-J32)*7/9 | K34: =K32+(K33-K32)*8/9 | L34: =L32+(L33-L32)*9/9
A35: 运营费用 ($B) | B35: =B24*B34 | C35: =C24*C34 | D35: =D24*D34 | E35: =E24*E34 | F35: =F24*F34 | G35: =G24*G34 | H35: =H24*H34 | I35: =I24*I34 | ... L35: =L24*L34
A36: EBIT ($B) | B36: =B31-B35 | C36: =C31-C35 | D36: =D31-D35 | E36: =E31-E35 | F36: =F31-F35 | G36: =G31-G35 | H36: =H31-H35 | I36: =I31-I35 | ... L36: =L31-L35
A37: 税率 | B37: ='假设'!$F$33 | C37: ='假设'!$F$33 | D37: ='假设'!$F$33 | E37: ='假设'!$F$33 | F37: ='假设'!$F$33 | G37: ='假设'!$F$33 | H37: ='假设'!$F$33 | I37: ='假设'!$F$33 | ... L37: ='假设'!$F$33
A38: 净利润 ($B) | B38: 120067000000 | C38: =C36*(1-C37) | D38: =D36*(1-D37) | E38: =E36*(1-E37) | F38: =F36*(1-F37) | G38: =G36*(1-G37) | H38: =H36*(1-H37) | I38: =I36*(1-I37) | J38: =J36*(1-J37) | ... L38: =L36*(1-L37)
A40: --- 估值 ---
A41: 起始PE | B41: ='假设'!$F$35 | C41: ='假设'!$F$35 | D41: ='假设'!$F$35 | E41: ='假设'!$F$35 | F41: ='假设'!$F$35 | G41: ='假设'!$F$35 | H41: ='假设'!$F$35 | I41: ='假设'!$F$35 | ... L41: ='假设'!$F$35
A42: 终年PE | B42: ='假设'!$F$36 | C42: ='假设'!$F$36 | D42: ='假设'!$F$36 | E42: ='假设'!$F$36 | F42: ='假设'!$F$36 | G42: ='假设'!$F$36 | H42: ='假设'!$F$36 | I42: ='假设'!$F$36 | ... L42: ='假设'!$F$36
A43: 目标PE | B43: 45.05714 | C43: =C41+(C42-C41)*0/9 | D43: =D41+(D42-D41)*1/9 | E43: =E41+(E42-E41)*2/9 | F43: =F41+(F42-F41)*3/9 | G43: =G41+(G42-G41)*4/9 | H43: =H41+(H42-H41)*5/9 | I43: =I41+(I42-I41)*6/9 | J43: =J41+(J42-J41)*7/9 | K43: =K41+(K42-K41)*8/9 | L43: =L41+(L42-L41)*9/9
...
